{"timestamp":"2025-06-12T06:05:14.436779","level":"ERROR","logger":"gattonero","message":"Główny proces przetwarzania nie powiódł się: Failed to load image uploads\\m1.tif: Image file not found: uploads\\m1.tif","module":"development_logger","function":"error","line":305,"request_id":null,"operation_id":null,"algorithm_id":null,"user_session":null,"performance_data":null,"exception":"Traceback (most recent call last):\n  File \"D:\\projects\\gatto-ps-ai\\app\\algorithms\\algorithm_01_palette\\algorithm_gpu_cpu_fallback.py\", line 21, in safe_image_load\n    if not path_obj.exists(): raise ImageProcessingError(f\"Image file not found: {image_path}\")\napp.algorithms.algorithm_01_palette.algorithm_gpu_exceptions.ImageProcessingError: Image file not found: uploads\\m1.tif\n\nDuring handling of the above exception, another exception occurred:\n\nTraceback (most recent call last):\n  File \"D:\\projects\\gatto-ps-ai\\app\\algorithms\\algorithm_01_palette\\algorithm_gpu.py\", line 204, in process_images\n    master_image = cpu.safe_image_load(master_path, self.logger)\n  File \"D:\\projects\\gatto-ps-ai\\app\\algorithms\\algorithm_01_palette\\algorithm_gpu_cpu_fallback.py\", line 31, in safe_image_load\n    raise ImageProcessingError(f\"Failed to load image {image_path}: {e}\")\napp.algorithms.algorithm_01_palette.algorithm_gpu_exceptions.ImageProcessingError: Failed to load image uploads\\m1.tif: Image file not found: uploads\\m1.tif"}
{"timestamp":"2025-06-12T06:05:14.441772","level":"ERROR","logger":"gattonero","message":"Główny proces przetwarzania nie powiódł się: Failed to load image uploads\\m1.tif: Image file not found: uploads\\m1.tif","module":"development_logger","function":"error","line":305,"request_id":null,"operation_id":null,"algorithm_id":null,"user_session":null,"performance_data":null,"exception":"Traceback (most recent call last):\n  File \"D:\\projects\\gatto-ps-ai\\app\\algorithms\\algorithm_01_palette\\algorithm_gpu_cpu_fallback.py\", line 21, in safe_image_load\n    if not path_obj.exists(): raise ImageProcessingError(f\"Image file not found: {image_path}\")\napp.algorithms.algorithm_01_palette.algorithm_gpu_exceptions.ImageProcessingError: Image file not found: uploads\\m1.tif\n\nDuring handling of the above exception, another exception occurred:\n\nTraceback (most recent call last):\n  File \"D:\\projects\\gatto-ps-ai\\app\\algorithms\\algorithm_01_palette\\algorithm_gpu.py\", line 204, in process_images\n    master_image = cpu.safe_image_load(master_path, self.logger)\n  File \"D:\\projects\\gatto-ps-ai\\app\\algorithms\\algorithm_01_palette\\algorithm_gpu_cpu_fallback.py\", line 31, in safe_image_load\n    raise ImageProcessingError(f\"Failed to load image {image_path}: {e}\")\napp.algorithms.algorithm_01_palette.algorithm_gpu_exceptions.ImageProcessingError: Failed to load image uploads\\m1.tif: Image file not found: uploads\\m1.tif"}
{"timestamp":"2025-06-12T06:05:14.445771","level":"ERROR","logger":"gattonero","message":"Główny proces przetwarzania nie powiódł się: Failed to load image uploads\\m1.tif: Image file not found: uploads\\m1.tif","module":"development_logger","function":"error","line":305,"request_id":null,"operation_id":null,"algorithm_id":null,"user_session":null,"performance_data":null,"exception":"Traceback (most recent call last):\n  File \"D:\\projects\\gatto-ps-ai\\app\\algorithms\\algorithm_01_palette\\algorithm_gpu_cpu_fallback.py\", line 21, in safe_image_load\n    if not path_obj.exists(): raise ImageProcessingError(f\"Image file not found: {image_path}\")\napp.algorithms.algorithm_01_palette.algorithm_gpu_exceptions.ImageProcessingError: Image file not found: uploads\\m1.tif\n\nDuring handling of the above exception, another exception occurred:\n\nTraceback (most recent call last):\n  File \"D:\\projects\\gatto-ps-ai\\app\\algorithms\\algorithm_01_palette\\algorithm_gpu.py\", line 204, in process_images\n    master_image = cpu.safe_image_load(master_path, self.logger)\n  File \"D:\\projects\\gatto-ps-ai\\app\\algorithms\\algorithm_01_palette\\algorithm_gpu_cpu_fallback.py\", line 31, in safe_image_load\n    raise ImageProcessingError(f\"Failed to load image {image_path}: {e}\")\napp.algorithms.algorithm_01_palette.algorithm_gpu_exceptions.ImageProcessingError: Failed to load image uploads\\m1.tif: Image file not found: uploads\\m1.tif"}
{"timestamp":"2025-06-12T06:05:14.450243","level":"ERROR","logger":"gattonero","message":"Główny proces przetwarzania nie powiódł się: Failed to load image uploads\\m1.tif: Image file not found: uploads\\m1.tif","module":"development_logger","function":"error","line":305,"request_id":null,"operation_id":null,"algorithm_id":null,"user_session":null,"performance_data":null,"exception":"Traceback (most recent call last):\n  File \"D:\\projects\\gatto-ps-ai\\app\\algorithms\\algorithm_01_palette\\algorithm_gpu_cpu_fallback.py\", line 21, in safe_image_load\n    if not path_obj.exists(): raise ImageProcessingError(f\"Image file not found: {image_path}\")\napp.algorithms.algorithm_01_palette.algorithm_gpu_exceptions.ImageProcessingError: Image file not found: uploads\\m1.tif\n\nDuring handling of the above exception, another exception occurred:\n\nTraceback (most recent call last):\n  File \"D:\\projects\\gatto-ps-ai\\app\\algorithms\\algorithm_01_palette\\algorithm_gpu.py\", line 204, in process_images\n    master_image = cpu.safe_image_load(master_path, self.logger)\n  File \"D:\\projects\\gatto-ps-ai\\app\\algorithms\\algorithm_01_palette\\algorithm_gpu_cpu_fallback.py\", line 31, in safe_image_load\n    raise ImageProcessingError(f\"Failed to load image {image_path}: {e}\")\napp.algorithms.algorithm_01_palette.algorithm_gpu_exceptions.ImageProcessingError: Failed to load image uploads\\m1.tif: Image file not found: uploads\\m1.tif"}
